<?xml version="1.0" ?>
<sdf version="1.4">
  <model name="waffle_pi_1">  
<pose>0 0 0 0 0 0</pose>
    <link name="base">

      <inertial>
        <pose>-0.064 0 0.048 0 0 0</pose>
        <inertia>
          <ixx>0.001</ixx>
          <ixy>0.000</ixy>
          <ixz>0.000</ixz>
          <iyy>0.001</iyy>
          <iyz>0.000</iyz>
          <izz>0.001</izz>
        </inertia>
        <mass>1.0</mass>
      </inertial>

      <collision name="base_collision">
        <pose>-0.064 0 0.048 0 0 0</pose>
        <geometry>
          <box>
            <size>0.265 0.265 0.089</size>
          </box>
        </geometry>
      </collision>

      <visual name="base_visual">
        <pose>-0.064 0 0 0 0 0</pose>
        <geometry>
          <mesh>
            <uri>model://waffle_pi_1/meshes/waffle_pi_base.dae</uri>
            <scale>0.001 0.001 0.001</scale>
          </mesh>
        </geometry>
      </visual>

      <collision name="right_caster_collision">
        <pose>-0.177 -0.064 -0.004 0 0 0</pose>
        <geometry>
          <sphere>
            <radius>0.005000</radius>
          </sphere>
        </geometry>
        <surface>
          <friction>
            <ode>
              <mu>100000.0</mu>
              <mu2>100000.0</mu2>
              <fdir1>0 0 0</fdir1>
              <slip1>0</slip1>
              <slip2>0</slip2>
            </ode>
          </friction>
        </surface>
      </collision>

      <collision name="left_caster_collision">
        <pose>-0.177 0.064 -0.004 0 0 0</pose>
        <geometry>
          <sphere>
            <radius>0.005000</radius>
          </sphere>
        </geometry>
        <surface>
          <friction>
            <ode>
              <mu>100000.0</mu>
              <mu2>100000.0</mu2>
              <fdir1>0 0 0</fdir1>
              <slip1>0</slip1>
              <slip2>0</slip2>
            </ode>
          </friction>
        </surface>
      </collision>
    </link>

    <link name="lidar">    
      <inertial>
        <pose>-0.052 0 0.111 0 0 0</pose>
        <inertia>
          <ixx>0.001</ixx>
          <ixy>0.000</ixy>
          <ixz>0.000</ixz>
          <iyy>0.001</iyy>
          <iyz>0.000</iyz>
          <izz>0.001</izz>
        </inertia>
        <mass>0.125</mass>
      </inertial>

      <collision name="lidar_sensor_collision">
        <pose>-0.052 0 0.111 0 0 0</pose>
        <geometry>
          <cylinder>
            <radius>0.0508</radius>
            <length>0.055</length>
          </cylinder>
        </geometry>
      </collision>

      <visual name="lidar_sensor_visual">
        <pose>-0.064 0 0.121 0 0 0</pose>
        <geometry>
          <mesh>
            <uri>model://waffle_pi_1/meshes/lds.dae</uri>
            <scale>0.001 0.001 0.001</scale>
          </mesh>
        </geometry>
      </visual>

      <sensor name="hls_lfcd_lds" type="ray">
        <always_on>1</always_on>
        <visualize>0</visualize>
        <pose>-0.064 0 0.121 0 0 0</pose>
        <update_rate>1800</update_rate>
        <ray>
          <scan>
            <horizontal>
              <samples>360</samples>
              <resolution>1.000000</resolution>
              <min_angle>0.000000</min_angle>
              <max_angle>6.280000</max_angle>
            </horizontal>
          </scan>
          <range>
            <min>0.120000</min>
            <max>3.5</max>
            <resolution>0.015000</resolution>
          </range>
          <noise>
            <type>gaussian</type>
            <mean>0.0</mean>
            <stddev>0.01</stddev>
          </noise>
        </ray>
      </sensor>
    </link>

    <link name="image">
      <inertial>
        <pose>-0.069 0 0.104 0 0 0</pose>
        <inertia>
          <ixx>0.001</ixx>
          <ixy>0.000</ixy>
          <ixz>0.000</ixz>
          <iyy>0.001</iyy>
          <iyz>0.000</iyz>
          <izz>0.001</izz>
        </inertia>
        <mass>0.035</mass>
      </inertial>

      <collision name="image_collision">
        <pose>-0.069 0 0.104 0 0 0</pose>
        <geometry>
          <box>
            <size>0.008 0.130 0.022</size>
          </box>
        </geometry>
      </collision>

      <sensor name="raspberry_pi_cam" type="camera">
        <pose>0.076 0 0.094 0 0 0</pose>
        <always_on>1</always_on>
        <visualize>0</visualize>
        <update_rate>30</update_rate>
        <camera>
            <horizontal_fov>1.085595</horizontal_fov>
            <image>
                <width>640</width>
                <height>480</height>
                <format>R8G8B8</format>
            </image>
            <depth_camera></depth_camera>
            <clip>
                <near>0.02</near>
                <far>300</far>
            </clip>
        </camera>
      </sensor>
    </link>

    <link name="left_wheel">

      <inertial>
        <pose>0.0 0.144 0.023 -1.57 0 0</pose>
        <inertia>
          <ixx>0.001</ixx>
          <ixy>0.000</ixy>
          <ixz>0.000</ixz>
          <iyy>0.001</iyy>
          <iyz>0.000</iyz>
          <izz>0.001</izz>
        </inertia>
        <mass>0.1</mass>
      </inertial>

      <collision name="left_wheel_collision">
        <pose>0.0 0.144 0.023 -1.57 0 0</pose>
        <geometry>
          <cylinder>
            <radius>0.033</radius>
            <length>0.018</length>
          </cylinder>
        </geometry>
          <surface>
            <friction>
              <ode>
                <mu>100000.0</mu>
                <mu2>100000.0</mu2>
                <fdir1>0 0 0</fdir1>
                <slip1>0.0</slip1>
                <slip2>0.0</slip2>
              </ode>
          </friction>
        </surface>
      </collision>

      <visual name="left_wheel_visual">
        <pose>0.0 0.144 0.023 0 0 0</pose>
        <geometry>
          <mesh>
            <uri>model://waffle_pi_1/meshes/left_tire.dae</uri>
            <scale>0.001 0.001 0.001</scale>
          </mesh>
        </geometry>
      </visual>
    </link>

    <link name="right_wheel">

      <inertial>
        <pose>0.0 -0.144 0.023 -1.57 0 0</pose>
        <inertia>
          <ixx>0.001</ixx>
          <ixy>0.000</ixy>
          <ixz>0.000</ixz>
          <iyy>0.001</iyy>
          <iyz>0.000</iyz>
          <izz>0.001</izz>
        </inertia>
        <mass>0.1</mass>
      </inertial>
    
      <collision name="right_wheel_collision">
        <pose>0.0 -0.144 0.023 -1.57 0 0</pose>
        <geometry>
          <cylinder>
            <radius>0.033</radius>
            <length>0.018</length>
          </cylinder>
        </geometry>
          <surface>
            <friction>
              <ode>
                <mu>100000.0</mu>
                <mu2>100000.0</mu2>
                <fdir1>0 0 0</fdir1>
                <slip1>0.0</slip1>
                <slip2>0.0</slip2>
              </ode>
          </friction>
        </surface>
      </collision>

      <visual name="right_wheel_visual">
        <pose>0.0 -0.144 0.023 0 0 0</pose>
        <geometry>
          <mesh>
            <uri>model://waffle_pi_1/meshes/right_tire.dae</uri>
            <scale>0.001 0.001 0.001</scale>
          </mesh>
        </geometry>
      </visual>
    </link>

    <joint name="left_wheel_joint" type="revolute">
      <parent>base</parent>
      <child>left_wheel</child>
      <pose>0.0 0.144 0.023 -1.57 0 0</pose>
      <axis>
        <xyz>0 1 0</xyz>
      </axis>
    </joint>

    <joint name="right_wheel_joint" type="revolute">
      <parent>base</parent>
      <child>right_wheel</child>
      <pose>0.0 -0.144 0.023 -1.57 0 0</pose>
      <axis>
        <xyz>0 1 0</xyz>
      </axis>
    </joint>

    <joint name="lidar_joint" type="fixed">
      <parent>base</parent>
      <child>lidar</child>
      <pose>-0.064 0 0.121 0 0 0</pose>
      <axis>
        <xyz>0 0 1</xyz>
        <use_parent_model_frame>true</use_parent_model_frame>
      </axis>
    </joint>

    <joint name="image_joint" type="fixed">
      <parent>base</parent>
      <child>image</child>
      <pose>0.064 -0.065 0.094 0 0 0</pose>
      <axis>
        <xyz>0 0 1</xyz>
        <use_parent_model_frame>true</use_parent_model_frame>
      </axis>
    </joint>

  <model name="aruco_cube_1">
  <pose>-0.1 0 0.2 0 0 0</pose>
	
  <link name="base_cube">
        <collision name="collision_base">
          <geometry>
            <box>
              <size>0.1 0.1 0.1</size>
            </box>
          </geometry>
        </collision>
        <visual name="visual_base">
          <geometry>
            <box>
              <size>0.1 0.1 0.1</size>
            </box>
          </geometry>
        </visual>
    </link>

   <link name="artag_11">
      <pose>0.051 0 0 -1.57079633 0 -1.57079633</pose>
      <visual name="visual_artag_11">
        <geometry>
          <mesh>
            <uri>model://waffle_pi_1/meshes/artag_11.dae</uri>
          </mesh>
        </geometry>
      </visual>
      <collision name="collision_artag_11" >
        <geometry>
          <box>
            <size>0.09 0.09 0.001</size>
          </box>
        </geometry>
        <surface>
          <contact>
            <ode>
              <max_vel>0.1</max_vel>
              <min_depth>0.001</min_depth>
            </ode>
          </contact>
          <friction>
            <ode>
              <mu>1.0</mu>
              <mu2>1.0</mu2>
            </ode>
          </friction>
        </surface>
      </collision>
    </link>

  <link name="artag_12">
      <pose>0 -0.051 0 -1.57079633 0 -3.14159265</pose>
      <visual name="visual_artag_12">
        <geometry>
          <mesh>
            <uri>model://waffle_pi_1/meshes/artag_12.dae</uri>
          </mesh>
        </geometry>
      </visual>
      <collision name="collision_artag_12" >
        <geometry>
          <box>
            <size>0.09 0.09 0.001</size>
          </box>
        </geometry>
        <surface>
          <contact>
            <ode>
              <max_vel>0.1</max_vel>
              <min_depth>0.001</min_depth>
            </ode>
          </contact>
          <friction>
            <ode>
              <mu>1.0</mu>
              <mu2>1.0</mu2>
            </ode>
          </friction>
        </surface>
      </collision>
    </link>

   <link name="artag_13">
      <pose>-0.051 0 0 1.57079633 1.57079633 1.57079633</pose>
      <visual name="visual_artag_13">
        <geometry>
          <mesh>
            <uri>model://waffle_pi_1/meshes/artag_13.dae</uri>
          </mesh>
        </geometry>
      </visual>
      <collision name="collision_artag_13" >
        <geometry>
          <box>
            <size>0.09 0.09 0.001</size>
          </box>
        </geometry>
        <surface>
          <contact>
            <ode>
              <max_vel>0.1</max_vel>
              <min_depth>0.001</min_depth>
            </ode>
          </contact>
          <friction>
            <ode>
              <mu>1.0</mu>
              <mu2>1.0</mu2>
            </ode>
          </friction>
        </surface>
      </collision>
    </link>

  <link name="artag_14">
      <pose>0 0.05 0  -1.57079633 0 0</pose>
      <visual name="visual_artag_14">
        <geometry>
          <mesh>
            <uri>model://waffle_pi_1/meshes/artag_14.dae</uri>
          </mesh>
        </geometry>
      </visual>
      <collision name="collision_artag_14" >
        <geometry>
          <box>
            <size>0.09 0.09 0.001</size>
          </box>
        </geometry>
        <surface>
          <contact>
            <ode>
              <max_vel>0.1</max_vel>
              <min_depth>0.001</min_depth>
            </ode>
          </contact>
          <friction>
            <ode>
              <mu>1.0</mu>
              <mu2>1.0</mu2>
            </ode>
          </friction>
        </surface>
      </collision>
    </link>


  <joint name="base_to_tag11" type="fixed">
      <pose>0 0 0 0 0 0</pose>
      <parent>base_cube</parent>
      <child>artag_11</child>
      <axis>
        <dynamics>
          <damping>1</damping>
          <friction>0</friction>
        </dynamics>
        <limit>
          <effort>1.0</effort>
        </limit>
        <xyz>1 0 0</xyz>
        <use_parent_model_frame>true</use_parent_model_frame>
      </axis>
    </joint>

  <joint name="base_to_tag12" type="fixed">
      <pose>0 0 0 0 0 0</pose>
      <parent>base_cube</parent>
      <child>artag_12</child>
      <axis>
        <dynamics>
          <damping>1</damping>
          <friction>0</friction>
        </dynamics>
        <limit>
          <effort>1.0</effort>
        </limit>
        <xyz>0 -1 0</xyz>
        <use_parent_model_frame>true</use_parent_model_frame>
      </axis>
    </joint>

  <joint name="base_to_tag13" type="fixed">
      <pose>0 0 0 0 0 0</pose>
      <parent>base_cube</parent>
      <child>artag_13</child>
      <axis>
        <dynamics>
          <damping>1</damping>
          <friction>0</friction>
        </dynamics>
        <limit>
          <effort>1.0</effort>
        </limit>
        <xyz>-1 0 0</xyz>
        <use_parent_model_frame>true</use_parent_model_frame>
      </axis>
    </joint>

   <joint name="base_to_tag14" type="fixed">
      <pose>0 0 0 0 0 0</pose>
      <parent>base_cube</parent>
      <child>artag_14</child>
      <axis>
        <dynamics>
          <damping>1</damping>
          <friction>0</friction>
        </dynamics>
        <limit>
          <effort>1.0</effort>
        </limit>
        <xyz>0 1 0</xyz>
        <use_parent_model_frame>true</use_parent_model_frame>
      </axis>
    </joint>

   </model>


<joint name="base_to_cube" type="fixed">
      <pose>0 0 0 0 0 0</pose>
      <parent>base</parent>
      <child>aruco_cube_1</child>
      <axis>
        <dynamics>
          <damping>1</damping>
          <friction>0</friction>
        </dynamics>
        <limit>
          <effort>1.0</effort>
        </limit>
        <xyz>0 0 1</xyz>
        <use_parent_model_frame>true</use_parent_model_frame>
      </axis>
    </joint>

  </model>
</sdf>
